[2024-10-14T15:47:31.837+0000] {taskinstance.py:1125} INFO - Dependencies all met for dep_context=non-requeueable deps ti=<TaskInstance: final_project.Run_data_quality_checks manual__2024-10-14T15:47:27.030568+00:00 [queued]>
[2024-10-14T15:47:31.857+0000] {taskinstance.py:1125} INFO - Dependencies all met for dep_context=requeueable deps ti=<TaskInstance: final_project.Run_data_quality_checks manual__2024-10-14T15:47:27.030568+00:00 [queued]>
[2024-10-14T15:47:31.859+0000] {taskinstance.py:1331} INFO - Starting attempt 1 of 1
[2024-10-14T15:47:31.894+0000] {taskinstance.py:1350} INFO - Executing <Task(DataQualityOperator): Run_data_quality_checks> on 2024-10-14 15:47:27.030568+00:00
[2024-10-14T15:47:31.904+0000] {standard_task_runner.py:57} INFO - Started process 196 to run task
[2024-10-14T15:47:31.915+0000] {standard_task_runner.py:84} INFO - Running: ['***', 'tasks', 'run', 'final_project', 'Run_data_quality_checks', 'manual__2024-10-14T15:47:27.030568+00:00', '--job-id', '19', '--raw', '--subdir', 'DAGS_FOLDER/final_project.py', '--cfg-path', '/tmp/tmpj3ody335']
[2024-10-14T15:47:31.918+0000] {standard_task_runner.py:85} INFO - Job 19: Subtask Run_data_quality_checks
[2024-10-14T15:47:32.030+0000] {task_command.py:410} INFO - Running <TaskInstance: final_project.Run_data_quality_checks manual__2024-10-14T15:47:27.030568+00:00 [running]> on host 9df4383435fa
[2024-10-14T15:47:32.253+0000] {taskinstance.py:1570} INFO - Exporting env vars: AIRFLOW_CTX_DAG_OWNER='udacity' AIRFLOW_CTX_DAG_ID='final_project' AIRFLOW_CTX_TASK_ID='Run_data_quality_checks' AIRFLOW_CTX_EXECUTION_DATE='2024-10-14T15:47:27.030568+00:00' AIRFLOW_CTX_TRY_NUMBER='1' AIRFLOW_CTX_DAG_RUN_ID='manual__2024-10-14T15:47:27.030568+00:00'
[2024-10-14T15:47:32.256+0000] {taskinstance.py:1847} ERROR - Task failed with exception
Traceback (most recent call last):
  File "/opt/airflow/plugins/operators/data_quality.py", line 21, in execute
    records = redshift_hook.get_records(f"SELECT COUNT(*) FROM {self.table}")
AttributeError: 'DataQualityOperator' object has no attribute 'table'
[2024-10-14T15:47:32.274+0000] {taskinstance.py:1373} INFO - Marking task as FAILED. dag_id=final_project, task_id=Run_data_quality_checks, execution_date=20241014T154727, start_date=20241014T154731, end_date=20241014T154732
[2024-10-14T15:47:32.297+0000] {standard_task_runner.py:109} ERROR - Failed to execute job 19 for task Run_data_quality_checks ('DataQualityOperator' object has no attribute 'table'; 196)
[2024-10-14T15:47:32.330+0000] {local_task_job_runner.py:232} INFO - Task exited with return code 1
[2024-10-14T15:47:32.384+0000] {taskinstance.py:2674} INFO - 0 downstream tasks scheduled from follow-on schedule check
