[2024-10-14T15:52:43.748+0000] {taskinstance.py:1125} INFO - Dependencies all met for dep_context=non-requeueable deps ti=<TaskInstance: final_project.Run_data_quality_checks manual__2024-10-14T15:52:38.865653+00:00 [queued]>
[2024-10-14T15:52:43.767+0000] {taskinstance.py:1125} INFO - Dependencies all met for dep_context=requeueable deps ti=<TaskInstance: final_project.Run_data_quality_checks manual__2024-10-14T15:52:38.865653+00:00 [queued]>
[2024-10-14T15:52:43.767+0000] {taskinstance.py:1331} INFO - Starting attempt 1 of 1
[2024-10-14T15:52:43.801+0000] {taskinstance.py:1350} INFO - Executing <Task(DataQualityOperator): Run_data_quality_checks> on 2024-10-14 15:52:38.865653+00:00
[2024-10-14T15:52:43.819+0000] {standard_task_runner.py:57} INFO - Started process 308 to run task
[2024-10-14T15:52:43.831+0000] {standard_task_runner.py:84} INFO - Running: ['***', 'tasks', 'run', 'final_project', 'Run_data_quality_checks', 'manual__2024-10-14T15:52:38.865653+00:00', '--job-id', '27', '--raw', '--subdir', 'DAGS_FOLDER/final_project.py', '--cfg-path', '/tmp/tmpf9htzk3f']
[2024-10-14T15:52:43.838+0000] {standard_task_runner.py:85} INFO - Job 27: Subtask Run_data_quality_checks
[2024-10-14T15:52:43.965+0000] {task_command.py:410} INFO - Running <TaskInstance: final_project.Run_data_quality_checks manual__2024-10-14T15:52:38.865653+00:00 [running]> on host 9df4383435fa
[2024-10-14T15:52:44.209+0000] {taskinstance.py:1570} INFO - Exporting env vars: AIRFLOW_CTX_DAG_OWNER='udacity' AIRFLOW_CTX_DAG_ID='final_project' AIRFLOW_CTX_TASK_ID='Run_data_quality_checks' AIRFLOW_CTX_EXECUTION_DATE='2024-10-14T15:52:38.865653+00:00' AIRFLOW_CTX_TRY_NUMBER='1' AIRFLOW_CTX_DAG_RUN_ID='manual__2024-10-14T15:52:38.865653+00:00'
[2024-10-14T15:52:44.213+0000] {taskinstance.py:1847} ERROR - Task failed with exception
Traceback (most recent call last):
  File "/opt/airflow/plugins/operators/data_quality.py", line 21, in execute
    records = redshift_hook.get_records(f"SELECT COUNT(*) FROM {self.table}")
AttributeError: 'DataQualityOperator' object has no attribute 'table'
[2024-10-14T15:52:44.238+0000] {taskinstance.py:1373} INFO - Marking task as FAILED. dag_id=final_project, task_id=Run_data_quality_checks, execution_date=20241014T155238, start_date=20241014T155243, end_date=20241014T155244
[2024-10-14T15:52:44.263+0000] {standard_task_runner.py:109} ERROR - Failed to execute job 27 for task Run_data_quality_checks ('DataQualityOperator' object has no attribute 'table'; 308)
[2024-10-14T15:52:44.288+0000] {local_task_job_runner.py:232} INFO - Task exited with return code 1
[2024-10-14T15:52:44.342+0000] {taskinstance.py:2674} INFO - 0 downstream tasks scheduled from follow-on schedule check
